[INFO] 2022-06-17 21:18:02,319 (Local): BOOT
[ERROR] 2022-06-17 21:19:23,049 (Local): /home/lisa/.local/lib/python3.8/site-packages/discord/ext/commands/core.py:85: DeprecationWarning: logout is deprecated, use Client.close instead.
  ret = await coro(*args, **kwargs)

[ERROR] 2022-06-17 21:19:23,051 (Local): /home/lisa/.local/lib/python3.8/site-packages/discord/client.py:66: DeprecationWarning: Task.all_tasks() is deprecated, use asyncio.all_tasks() instead
  tasks = {t for t in task_retriever(loop=loop) if not t.done()}

[INFO] 2022-06-17 21:19:23,052 (Local): SHUTDOWN
[INFO] 2022-06-17 21:22:16,987 (Local): BOOT
[INFO] 2022-06-17 21:22:25,222 (Local): SHUTDOWN
[INFO] 2022-06-17 21:22:39,417 (Local): BOOT
[INFO] 2022-06-17 21:59:52,290 (Local): SHUTDOWN
[INFO] 2022-06-17 22:00:07,711 (Local): BOOT
[ERROR] 2022-06-17 22:00:31,916 (Local): Ignoring exception in command dm:
[ERROR] 2022-06-17 22:00:31,916 (Local): 

[ERROR] 2022-06-17 22:00:31,919 (Local): Traceback (most recent call last):

[ERROR] 2022-06-17 22:00:31,919 (Local): 
[ERROR] 2022-06-17 22:00:31,919 (Local):   File "/home/lisa/.local/lib/python3.8/site-packages/discord/ext/commands/core.py", line 85, in wrapped
    ret = await coro(*args, **kwargs)

[ERROR] 2022-06-17 22:00:31,919 (Local): 
[ERROR] 2022-06-17 22:00:31,919 (Local):   File "rolebot.py", line 65, in dm
    file = file=discord.File(fileName)

[ERROR] 2022-06-17 22:00:31,919 (Local): 
[ERROR] 2022-06-17 22:00:31,919 (Local):   File "/home/lisa/.local/lib/python3.8/site-packages/discord/file.py", line 73, in __init__
    self.fp = open(fp, 'rb')

[ERROR] 2022-06-17 22:00:31,919 (Local): 
[ERROR] 2022-06-17 22:00:31,919 (Local): FileNotFoundError: [Errno 2] No such file or directory: './logs/server.txt'

[ERROR] 2022-06-17 22:00:31,919 (Local): 
[ERROR] 2022-06-17 22:00:31,919 (Local): 
The above exception was the direct cause of the following exception:


[ERROR] 2022-06-17 22:00:31,919 (Local): 
[ERROR] 2022-06-17 22:00:31,919 (Local): Traceback (most recent call last):

[ERROR] 2022-06-17 22:00:31,919 (Local): 
[ERROR] 2022-06-17 22:00:31,919 (Local):   File "/home/lisa/.local/lib/python3.8/site-packages/discord/ext/commands/bot.py", line 939, in invoke
    await ctx.command.invoke(ctx)

[ERROR] 2022-06-17 22:00:31,919 (Local): 
[ERROR] 2022-06-17 22:00:31,919 (Local):   File "/home/lisa/.local/lib/python3.8/site-packages/discord/ext/commands/core.py", line 863, in invoke
    await injected(*ctx.args, **ctx.kwargs)

[ERROR] 2022-06-17 22:00:31,919 (Local): 
[ERROR] 2022-06-17 22:00:31,920 (Local):   File "/home/lisa/.local/lib/python3.8/site-packages/discord/ext/commands/core.py", line 94, in wrapped
    raise CommandInvokeError(exc) from exc

[ERROR] 2022-06-17 22:00:31,920 (Local): 
[ERROR] 2022-06-17 22:00:31,920 (Local): discord.ext.commands.errors.CommandInvokeError: Command raised an exception: FileNotFoundError: [Errno 2] No such file or directory: './logs/server.txt'

[ERROR] 2022-06-17 22:00:31,920 (Local): 
[INFO] 2022-06-17 22:08:45,054 (Local): SHUTDOWN
[INFO] 2022-06-17 22:08:49,963 (Local): BOOT
[ERROR] 2022-06-17 22:09:01,895 (Local): rolebot.py:59: RuntimeWarning: coroutine 'Messageable.send' was never awaited
  dm.send(str(ctx.author.id))
RuntimeWarning: Enable tracemalloc to get the object allocation traceback

[ERROR] 2022-06-17 22:09:01,896 (Local): Ignoring exception in command dm:
[ERROR] 2022-06-17 22:09:01,896 (Local): 

[ERROR] 2022-06-17 22:09:01,898 (Local): Traceback (most recent call last):

[ERROR] 2022-06-17 22:09:01,898 (Local): 
[ERROR] 2022-06-17 22:09:01,898 (Local):   File "/home/lisa/.local/lib/python3.8/site-packages/discord/ext/commands/core.py", line 85, in wrapped
    ret = await coro(*args, **kwargs)

[ERROR] 2022-06-17 22:09:01,899 (Local): 
[ERROR] 2022-06-17 22:09:01,899 (Local):   File "rolebot.py", line 66, in dm
    if fileName:

[ERROR] 2022-06-17 22:09:01,899 (Local): 
[ERROR] 2022-06-17 22:09:01,899 (Local): UnboundLocalError: local variable 'fileName' referenced before assignment

[ERROR] 2022-06-17 22:09:01,899 (Local): 
[ERROR] 2022-06-17 22:09:01,899 (Local): 
The above exception was the direct cause of the following exception:


[ERROR] 2022-06-17 22:09:01,899 (Local): 
[ERROR] 2022-06-17 22:09:01,899 (Local): Traceback (most recent call last):

[ERROR] 2022-06-17 22:09:01,899 (Local): 
[ERROR] 2022-06-17 22:09:01,900 (Local):   File "/home/lisa/.local/lib/python3.8/site-packages/discord/ext/commands/bot.py", line 939, in invoke
    await ctx.command.invoke(ctx)

[ERROR] 2022-06-17 22:09:01,900 (Local): 
[ERROR] 2022-06-17 22:09:01,900 (Local):   File "/home/lisa/.local/lib/python3.8/site-packages/discord/ext/commands/core.py", line 863, in invoke
    await injected(*ctx.args, **ctx.kwargs)

[ERROR] 2022-06-17 22:09:01,900 (Local): 
[ERROR] 2022-06-17 22:09:01,900 (Local):   File "/home/lisa/.local/lib/python3.8/site-packages/discord/ext/commands/core.py", line 94, in wrapped
    raise CommandInvokeError(exc) from exc

[ERROR] 2022-06-17 22:09:01,900 (Local): 
[ERROR] 2022-06-17 22:09:01,900 (Local): discord.ext.commands.errors.CommandInvokeError: Command raised an exception: UnboundLocalError: local variable 'fileName' referenced before assignment

[ERROR] 2022-06-17 22:09:01,900 (Local): 
[INFO] 2022-06-17 22:10:50,275 (Local): SHUTDOWN
[INFO] 2022-06-17 22:10:54,481 (Local): BOOT
[ERROR] 2022-06-17 22:11:02,999 (Local): rolebot.py:60: RuntimeWarning: coroutine 'Messageable.send' was never awaited
  dm.send(str(ctx.author.id))
RuntimeWarning: Enable tracemalloc to get the object allocation traceback

[INFO] 2022-06-17 22:11:24,900 (Local): SHUTDOWN
[INFO] 2022-06-17 22:11:28,978 (Local): BOOT
